Workbook

Sheet Linear Model
B2: R Script | D2: Results
B3: library(tidyverse) | D3: {=_xll.RScript.Evaluate(B3, TRUE)} -> OK
B4: x <- rnorm(50) | D4: {=_xll.RScript.Evaluate(B4)} -> x
B5: y <- rnorm(50) | D5: {=_xll.RScript.Evaluate(B5)} -> y
B6: df <- data.frame(x = x, y = y) | D6: {=_xll.RScript.Evaluate(B6)} -> df
B7: fm <- lm(y ~ x) | D7: {=_xll.RScript.Evaluate(B7)} -> fm
B19: fm | D19: {=_xll.RScript.Evaluate(B19)} -> coefficients | E19: {=TRANSPOSE(_xll.RScript.Evaluate($B$19&"$"&D19))} -> 0.083242921 | F19: -0.096405257
D20: residuals | E20: {=TRANSPOSE(_xll.RScript.Evaluate($B$19&"$"&D20))} -> -0.22552153 | F20: 1.2962435 | G20: -0.70252824 | H20: 0.22715919 | I20: 0.03604656 | J20: -0.41442956 | K20: -1.0657924 | L20: -0.44830921 | M20: -0.33672445 | N20: -0.18045643 | O20: 0.35808251 | P20: -0.024805537 | Q20: 0.91759606 | R20: 1.0447528 | S20: 0.9032822 | T20: -1.0003299 | U20: -0.85496882 | V20: 1.0838993 | W20: -0.37039486 | X20: 1.6441217 | Y20: 0.96936248 | Z20: 0.13073483 | AA20: -1.2945693 | AB20: 0.3042332 | AC20: 0.31593178 | AD20: -0.37845518 | AE20: -0.33171287 | AF20: -0.0017095233 | AG20: 0.4063209 | AH20: 0.57771269 | AI20: -0.60172106 | AJ20: 0.50724592 | AK20: 1.2787823 | AL20: -0.25270072 | AM20: -0.61370926 | AN20: -0.6137095 | AO20: -1.0131896 | AP20: 0.6620305 | AQ20: -1.561074 | AR20: -1.3236521 | AS20: -0.22164474 | AT20: 0.72632694 | AU20: -2.6404001 | AV20: 0.39116241 | AW20: 0.59967124 | AX20: 0.70162069 | AY20: 1.1487103 | AZ20: 0.54963781 | BA20: -0.017436701 | BB20: -0.29072234
D21: effects | E21: {=TRANSPOSE(_xll.RScript.Evaluate($B$19&"$"&D21))} -> -0.54506832 | F21: 0.75700405 | G21: -0.62028195 | H21: 0.42000021 | I21: 0.16184924 | J21: -0.26875404 | K21: -1.1557701 | L21: -0.43765752 | M21: -0.098646482 | N21: 0.18003721 | O21: 0.61921867 | P21: 0.10558747 | Q21: 0.82331492 | R21: 0.87723947 | S21: 0.90472544 | T21: -0.97462734 | U21: -0.83236167 | V21: 1.3970943 | W21: -0.3768871 | X21: 1.5364524 | Y21: 0.97346138 | Z21: -0.00025134652 | AA21: -1.5049487 | AB21: 0.19529899 | AC21: 0.63631039 | AD21: -0.48525734 | AE21: -0.61393556 | AF21: -0.036941018 | AG21: 0.56143641 | AH21: 0.42566745 | AI21: -0.51977907 | AJ21: 0.76370751 | AK21: 1.6020939 | AL21: -0.38863075 | AM21: -0.62499124 | AN21: -0.83085553 | AO21: -0.93302109 | AP21: 0.88035338 | AQ21: -1.4180682 | AR21: -1.1254342 | AS21: -0.38117889 | AT21: 0.52271792 | AU21: -2.4822514 | AV21: 0.094128002 | AW21: 0.54073033 | AX21: 0.89473822 | AY21: 1.1500417 | AZ21: 0.68135861 | BA21: 0.24352052 | BB21: -0.51371264
D22: rank | E22: {=TRANSPOSE(_xll.RScript.Evaluate($B$19&"$"&D22))} -> 2
D23: fitted.values | E23: {=TRANSPOSE(_xll.RScript.Evaluate($B$19&"$"&D23))} -> 0.060070571 | F23: 0.011707043 | G23: 0.10861539 | H23: 0.17712385 | I23: 0.13559662 | J23: 0.14790695 | K23: 0.0019303662 | L23: 0.064265765 | M23: 0.20514611 | N23: 0.28097711 | O23: 0.21942962 | P23: 0.13844012 | Q23: -0.00073540208 | R23: -0.046099453 | S23: 0.058561538 | T23: 0.073589085 | U23: 0.071671629 | V23: 0.25167772 | W23: 0.053645865 | X23: -0.0090287304 | Y23: 0.060206599 | Z23: -0.023472525 | AA23: -0.072653051 | AB23: -0.0098123241 | AC23: 0.25612766 | AD23: -0.008491612 | AE23: -0.11715674 | AF23: 0.035843193 | AG23: 0.15375459 | AH23: -0.036517667 | AI23: 0.1084269 | AJ23: 0.21653393 | AK23: 0.25794453 | AL23: -0.02653502 | AM23: 0.05067884 | AN23: -0.076844677 | AO23: 0.10732831 | AP23: 0.19290872 | AQ23: 0.14625319 | AR23: 0.18045458 | AS23: -0.041156704 | AT23: -0.068459111 | AU23: 0.15563352 | AV23: -0.12633193 | AW23: 0.021156276 | AX23: 0.17729513 | AY23: 0.05849224 | AZ23: 0.13926263 | BA23: 0.21931878 | BB23: -0.080464941
D24: assign | E24: {=TRANSPOSE(_xll.RScript.Evaluate($B$19&"$"&D24))} -> 0 | F24: 1
D25: qr | E25: {=TRANSPOSE(_xll.RScript.Evaluate($B$19&"$"&D25))} -> qr | F25: qraux | G25: pivot | H25: tol | I25: rank
D26: df.residual | E26: {=TRANSPOSE(_xll.RScript.Evaluate($B$19&"$"&D26))} -> 48
D27: xlevels | E27: {=TRANSPOSE(_xll.RScript.Evaluate($B$19&"$"&D27))} -> List of 0 objects.
D28: call | E28: {=TRANSPOSE(_xll.RScript.Evaluate($B$19&"$"&D28))} -> lm(formula = y ~ x)
D29: terms | E29: {=TRANSPOSE(_xll.RScript.Evaluate($B$19&"$"&D29))} -> y ~ x
D30: model | E30: {=TRANSPOSE(_xll.RScript.Evaluate($B$19&"$"&D30))} -> Index | F30: 1 | G30: 2 | H30: 3 | I30: 4 | J30: 5 | K30: 6 | L30: 7 | M30: 8 | N30: 9 | O30: 10 | P30: 11 | Q30: 12 | R30: 13 | S30: 14 | T30: 15 | U30: 16 | V30: 17 | W30: 18 | X30: 19 | Y30: 20 | Z30: 21 | AA30: 22 | AB30: 23 | AC30: 24 | AD30: 25 | AE30: 26 | AF30: 27 | AG30: 28 | AH30: 29 | AI30: 30 | AJ30: 31 | AK30: 32 | AL30: 33 | AM30: 34 | AN30: 35 | AO30: 36 | AP30: 37 | AQ30: 38 | AR30: 39 | AS30: 40 | AT30: 41 | AU30: 42 | AV30: 43 | AW30: 44 | AX30: 45 | AY30: 46 | AZ30: 47 | BA30: 48 | BB30: 49 | BC30: 50
E31: y | F31: -0.16545096 | G31: 1.3079505 | H31: -0.59391285 | I31: 0.40428304 | J31: 0.17164318 | K31: -0.26652261 | L31: -1.063862 | M31: -0.38404345 | N31: -0.13157834 | O31: 0.10052068 | P31: 0.57751213 | Q31: 0.11363458 | R31: 0.91686065 | S31: 0.99865335 | T31: 0.96184374 | U31: -0.9267408 | V31: -0.78329719 | W31: 1.3355771 | X31: -0.31674899 | Y31: 1.6350929 | Z31: 1.0295691 | AA31: 0.10726231 | AB31: -1.3672224 | AC31: 0.29442088 | AD31: 0.57205943 | AE31: -0.38694679 | AF31: -0.44886961 | AG31: 0.034133669 | AH31: 0.5600755 | AI31: 0.54119502 | AJ31: -0.49329417 | AK31: 0.72377985 | AL31: 1.5367268 | AM31: -0.27923574 | AN31: -0.56303042 | AO31: -0.69055418 | AP31: -0.9058613 | AQ31: 0.85493922 | AR31: -1.4148208 | AS31: -1.1431975 | AT31: -0.26280145 | AU31: 0.65786783 | AV31: -2.4847666 | AW31: 0.26483048 | AX31: 0.62082752 | AY31: 0.87891583 | AZ31: 1.2072026 | BA31: 0.68890044 | BB31: 0.20188207 | BC31: -0.37118728
E32: x | F32: 0.24036397 | G32: 0.74203296 | H32: -0.26318556 | I32: -0.97381548 | J32: -0.54305852 | K32: -0.67075212 | L32: 0.84344524 | M32: 0.19684773 | N32: -1.2644869 | O32: -2.0510727 | P32: -1.412648 | Q32: -0.57255382 | R32: 0.87109693 | S32: 1.3416527 | T32: 0.25601698 | U32: 0.10013807 | V32: 0.1200276 | W32: -1.7471536 | X32: 0.30700666 | Y32: 0.95712262 | Z32: 0.23895297 | AA32: 1.1069463 | AB32: 1.61709 | AC32: 0.96525074 | AD32: -1.7933123 | AE32: 0.95155115 | AF32: 2.0787213 | AG32: 0.49167162 | AH32: -0.731409 | AI32: 1.242262 | AJ32: -0.26123032 | AK32: -1.3826115 | AL32: -1.8121585 | AM32: 1.1387132 | AN32: 0.33778325 | AO32: 1.6605692 | AP32: -0.24983484 | AQ32: -1.13755 | AR32: -0.65359783 | AS32: -1.0083647 | AT32: 1.2903822 | AU32: 1.5735867 | AV32: -0.75089885 | AW32: 2.1738945 | AX32: 0.64401722 | AY32: -0.97559216 | AZ32: 0.2567358 | BA32: -0.58108559 | BB32: -1.4114983 | BC32: 1.6981217
B34: summary(fm) | D34: {=_xll.RScript.Evaluate(B34)} -> call | E34: {=TRANSPOSE(_xll.RScript.Evaluate($B$34&"$"&D34))} -> lm(formula = y ~ x)
B35: as.data.frame(as.array(summary(fm$residuals))) | D35: terms | E35: {=TRANSPOSE(_xll.RScript.Evaluate($B$34&"$"&D35))} -> y ~ x
D36: residuals | E36: {=TRANSPOSE(_xll.RScript.Evaluate($B$34&"$"&D36))} -> -0.22552153 | F36: 1.2962435 | G36: -0.70252824 | H36: 0.22715919 | I36: 0.03604656 | J36: -0.41442956 | K36: -1.0657924 | L36: -0.44830921 | M36: -0.33672445 | N36: -0.18045643 | O36: 0.35808251 | P36: -0.024805537 | Q36: 0.91759606 | R36: 1.0447528 | S36: 0.9032822 | T36: -1.0003299 | U36: -0.85496882 | V36: 1.0838993 | W36: -0.37039486 | X36: 1.6441217 | Y36: 0.96936248 | Z36: 0.13073483 | AA36: -1.2945693 | AB36: 0.3042332 | AC36: 0.31593178 | AD36: -0.37845518 | AE36: -0.33171287 | AF36: -0.0017095233 | AG36: 0.4063209 | AH36: 0.57771269 | AI36: -0.60172106 | AJ36: 0.50724592 | AK36: 1.2787823 | AL36: -0.25270072 | AM36: -0.61370926 | AN36: -0.6137095 | AO36: -1.0131896 | AP36: 0.6620305 | AQ36: -1.561074 | AR36: -1.3236521 | AS36: -0.22164474 | AT36: 0.72632694 | AU36: -2.6404001 | AV36: 0.39116241 | AW36: 0.59967124 | AX36: 0.70162069 | AY36: 1.1487103 | AZ36: 0.54963781 | BA36: -0.017436701 | BB36: -0.29072234
D37: coefficients
D38: aliased | E38: {=TRANSPOSE(_xll.RScript.Evaluate($B$34&"$"&D38))} -> FALSE | F38: FALSE
D39: sigma | E39: {=TRANSPOSE(_xll.RScript.Evaluate($B$34&"$"&D39))} -> 0.85537163
D40: df | E40: {=TRANSPOSE(_xll.RScript.Evaluate($B$34&"$"&D40))} -> 2 | F40: 48 | G40: 2
D41: r.squared | E41: {=TRANSPOSE(_xll.RScript.Evaluate($B$34&"$"&D41))} -> 0.016055218
D42: adj.r.squared | E42: {=TRANSPOSE(_xll.RScript.Evaluate($B$34&"$"&D42))} -> -0.0044436312
D43: fstatistic | E43: {=TRANSPOSE(_xll.RScript.Evaluate($B$34&"$"&D43))} -> 0.78322534 | F43: 1 | G43: 48
D44: cov.unscaled | E44: {=TRANSPOSE(_xll.RScript.Evaluate($B$34&"$"&D44))} -> 0.020066187 | F44: -0.0010360667
E45: -0.0010360667 | F45: 0.016218288
B47: summary(fm$residuals) | D47: {=_xll.RScript.Evaluate(B35)} -> Index | E47: Var1 | F47: Freq | H47: {=_xll.RScript.Evaluate(B47,"DataFrame")} -> Exception: Error in dimnames(x) <- dnx : 'dimnames' applied to non-array
D48: 1 | E48: Min. | F48: -2.6404001
D49: 2 | E49: 1st Qu. | F49: -0.4398393
D50: 3 | E50: Median | F50: -0.0095731122
D51: 4 | E51: Mean | F51: 1.2543135e-17
D52: 5 | E52: 3rd Qu. | F52: 0.5941816
D53: 6 | E53: Max. | F53: 1.6441217
B55: ="coef = round(as.data.frame("&B34&"$"&D37&"), 4)" -> coef = round(as.data.frame(summary(fm)$coefficients), 4) | D55: {=_xll.RScript.Evaluate(B55)} -> coef | E55: {=_xll.RScript.Evaluate(D55)} -> Index | F55: Estimate | G55: Std. Error | H55: t value | I55: Pr(>|t|) | K55: {=_xll.RScript.Evaluate(B56, "DataFrame")} -> Index | L55: Estimate | M55: Std. Error | N55: t value | O55: Pr(>|t|)
...

Sheet Summary Dashboard
B2: Summary
B3: ="Call: "&'Linear Model'!E34 -> Call: lm(formula = y ~ x)
B5: Residuals | D5: {=TRANSPOSE('Linear Model'!E48:F53)} -> Min. | E5: 1st Qu. | F5: Median | G5: Mean | H5: 3rd Qu. | I5: Max.
D6: -2.6404001 | E6: -0.4398393 | F6: -0.0095731122 | G6: 1.2543135e-17 | H6: 0.5941816 | I6: 1.6441217
B8: Coefficients | D8: {=_xlfn.ANCHORARRAY('Linear Model'!E55)} -> Index | E8: Estimate | F8: Std. Error | G8: t value | H8: Pr(>|t|)
D9: (Intercept) | E9: 0.0832 | F9: 0.1212 | G9: 0.687 | H9: 0.4954
D10: x | E10: -0.0964 | F10: 0.1089 | G10: -0.885 | H10: 0.3806
B12: ="Residual standard error: "&ROUND('Linear Model'!E39, 3)&" on "&'Linear Model'!E26&" degrees of freedom" -> Residual standard error: 0.855 on 48 degrees of freedom
B13: ="Multiple R-squared: "&ROUND('Linear Model'!E41, 4) -> Multiple R-squared: 0.0161 | C13: ="Adjusted R-squared: "&ROUND('Linear Model'!E42, 4) -> Adjusted R-squared: -0.0044
B14: ="F-statistic: "&ROUND('Linear Model'!E43, 2)&" on "&'Linear Model'!F43&" and "&'Linear Model'!G43&" DF" -> F-statistic: 0.78 on 1 and 48 DF
B16: ANOVA | D16: {=_xlfn.ANCHORARRAY('Linear Model'!E59)} -> Index | E16: Df | F16: Sum Sq | G16: Mean Sq | H16: F value | I16: Pr(>F)
D17: x | E17: 1 | F17: 0.26452253 | G17: 0.26452253 | H17: 0.36701131 | I17: 0.54749205
D18: Residuals | E18: 48 | F18: 34.595885 | G18: 0.72074761

Sheet Predictions
B2: x <- rnorm(15) | C2: {=_xll.RScript.Evaluate(B2)} -> x
B3: y <- x + rnorm(15) | C3: {=_xll.RScript.Evaluate(B3)} -> y
B4: predict(lm(y ~ x)) | C4: {=TRANSPOSE(_xll.RScript.Evaluate(B4))} -> 0.030791979 | D4: 0.10351232 | E4: 0.11437892 | F4: 0.27957318 | G4: 0.24703052 | H4: 0.28799151 | I4: 0.16412511 | J4: 0.21252099 | K4: 0.089110367 | L4: 0.29343343 | M4: 0.0048538344 | N4: 0.18922968 | O4: 0.13725927 | P4: 0.10332716 | Q4: 0.21914587
B5: new <- data.frame(x = seq(-3, 3, 0.5)) | C5: {=_xll.RScript.Evaluate(B5)} -> new
B6: predict(lm(y ~ x), new, se.fit = TRUE) | C6: {=TRANSPOSE(_xll.RScript.Evaluate(B6))} -> fit | D6: se.fit | E6: df | F6: residual.scale
B7: pred.w.plim <- predict(lm(y ~ x), new, interval = "prediction") | C7: {=TRANSPOSE(_xll.RScript.Evaluate(B7))} -> pred.w.plim
B8: pred.w.clim <- predict(lm(y ~ x), new, interval = "confidence") | C8: {=TRANSPOSE(_xll.RScript.Evaluate(B8))} -> pred.w.clim
B9: matplot(new$x, cbind(pred.w.clim, pred.w.plim[,-1]), lty = c(1,2,2,3,3), type = "l", ylab = "predicted y") | C9: {=TRANSPOSE(_xll.RScript.Evaluate(B9))} -> OK
B25: ## Prediction intervals, special cases
B26: ## The first three of these throw warnings
B27: w <- 1 + x^2 | C27: {=TRANSPOSE(_xll.RScript.Evaluate(B27))} -> w
B28: fit <- lm(y ~ x) | C28: {=TRANSPOSE(_xll.RScript.Evaluate(B28))} -> fit
B29: wfit <- lm(y ~ x, weights = w) | C29: {=TRANSPOSE(_xll.RScript.Evaluate(B29))} -> wfit
B30: predict(fit, interval = "prediction") | C30: {=TRANSPOSE(_xll.RScript.Evaluate(B30, "DataFrame"))} -> Index | D30: 1 | E30: 2 | F30: 3 | G30: 4 | H30: 5 | I30: 6 | J30: 7 | K30: 8 | L30: 9 | M30: 10 | N30: 11 | O30: 12 | P30: 13 | Q30: 14 | R30: 15
C31: fit | D31: -0.50015151 | E31: 1.8441742 | F31: -2.0305014 | G31: 0.073194832 | H31: -0.10620788 | I31: 0.13916473 | J31: 0.69308843 | K31: -0.62919516 | L31: 0.86435563 | M31: -0.15590931 | N31: -0.71193379 | O31: 1.3573223 | P31: -1.8294545 | Q31: 0.37952819 | R31: -1.8283894
C32: lwr | D32: -2.5017912 | E32: -0.34846774 | F32: -4.1978351 | G32: -1.9254671 | H32: -2.1021814 | I32: -1.8613132 | J32: -1.339933 | K32: -2.636132 | L32: -1.1848355 | M32: -2.1517215 | N32: -2.7231515 | O32: -0.75365002 | P32: -3.9629685 | Q32: -1.6313035 | R32: -3.9617331
C33: upr | D33: 1.5014882 | E33: 4.0368161 | F33: 0.13683218 | G33: 2.0718568 | H33: 1.8897657 | I33: 2.1396426 | J33: 2.7261099 | K33: 1.3777417 | L33: 2.9135468 | M33: 1.8399028 | N33: 1.299284 | O33: 3.4682947 | P33: 0.30405947 | Q33: 2.3903599 | R33: 0.30495434
B35: predict(wfit, interval = "prediction") | C35: {=TRANSPOSE(_xll.RScript.Evaluate(B35, "DataFrame"))} -> Index | D35: 1 | E35: 2 | F35: 3 | G35: 4 | H35: 5 | I35: 6 | J35: 7 | K35: 8 | L35: 9 | M35: 10 | N35: 11 | O35: 12 | P35: 13 | Q35: 14 | R35: 15
C36: fit | D36: -0.57016965 | E36: 1.3561014 | F36: -1.8276181 | G36: -0.099065967 | H36: -0.24647648 | I36: -0.044860225 | J36: 0.41028438 | K36: -0.67620144 | L36: 0.55101015 | M36: -0.28731485 | N36: -0.7441856 | O36: 0.95606799 | P36: -1.6624231 | Q36: 0.15264013 | R36: -1.6615479
C37: lwr | D37: -3.3436254 | E37: -0.23600258 | F37: -3.2808925 | G37: -3.1962694 | H37: -3.3563598 | I37: -3.1077717 | J37: -2.040232 | K37: -3.2845789 | L37: -1.6997863 | M37: -3.3792085 | N37: -3.2450838 | O37: -0.86392299 | P37: -3.1917202 | Q37: -2.6855787 | R37: -3.1913118
C38: upr | D38: 2.2032861 | E38: 2.9482054 | F38: -0.37434372 | G38: 2.9981375 | H38: 2.8634068 | I38: 3.0180512 | J38: 2.8608007 | K38: 1.9321761 | L38: 2.8018066 | M38: 2.8045788 | N38: 1.7567126 | O38: 2.776059 | P38: -0.13312605 | Q38: 2.990859 | R38: -0.13178409
B40: predict(wfit, new, interval = "prediction") | C40: {=TRANSPOSE(_xll.RScript.Evaluate(B40, "DataFrame"))} -> Index | D40: 1 | E40: 2 | F40: 3 | G40: 4 | H40: 5 | I40: 6 | J40: 7 | K40: 8 | L40: 9 | M40: 10 | N40: 11 | O40: 12 | P40: 13
C41: fit | D41: -2.3717347 | E41: -2.0082831 | F41: -1.6448315 | G41: -1.2813799 | H41: -0.91792829 | I41: -0.5544767 | J41: -0.19102511 | K41: 0.17242648 | L41: 0.53587807 | M41: 0.89932966 | N41: 1.2627812 | O41: 1.6262328 | P41: 1.9896844
C42: lwr | D42: -5.5843909 | E42: -5.1879906 | F42: -4.7983752 | G42: -4.4157144 | H42: -4.0401368 | I42: -3.671725 | J42: -3.3105131 | K42: -2.9564858 | L42: -2.6095783 | M42: -2.2696793 | N42: -1.9366339 | O42: -1.610249 | P42: -1.2902988
C43: upr | D43: 0.84092163 | E43: 1.1714245 | F43: 1.5087122 | G43: 1.8529547 | H43: 2.2042802 | I43: 2.5627716 | J43: 2.9284629 | K43: 3.3013387 | L43: 3.6813345 | M43: 4.0683386 | N43: 4.4621964 | O43: 4.8627147 | P43: 5.2696676
B45: predict(wfit, new, interval = "prediction", weights = (new$x)^2) | C45: {=TRANSPOSE(_xll.RScript.Evaluate(B45))} -> 0.49266117 | D45: 0.39401981 | E45: 0.29537846 | F45: 0.19673711 | G45: 0.098095752 | H45: -0.00054560167 | I45: -0.099186956 | J45: -0.19782831 | K45: -0.29646966 | L45: -0.39511102 | M45: -0.49375237 | N45: -0.59239373 | O45: -0.69103508
C46: -4.9267634 | D46: -4.4244061 | E46: -4.2430893 | F46: -4.7248538 | G46: -6.6156983 | H46: -13.127546 | I46: #NUM! | J46: -13.439467 | K46: -7.4463454 | L46: -6.1649112 | M46: -6.2111882 | N46: -6.7836341 | O46: -7.5835845
C47: 5.9120858 | D47: 5.2124457 | E47: 4.8338462 | F47: 5.118328 | G47: 6.8118899 | H47: 13.126455 | I47: #NUM! | J47: 13.04381 | K47: 6.8534061 | L47: 5.3746892 | M47: 5.2236835 | N47: 5.5988466 | O47: 6.2015144
B50: predict(wfit, new, interval = "prediction", weights = ~x^2) | C50: {=TRANSPOSE(_xll.RScript.Evaluate(B50))} -> 0.49266117 | D50: 0.39401981 | E50: 0.29537846 | F50: 0.19673711 | G50: 0.098095752 | H50: -0.00054560167 | I50: -0.099186956 | J50: -0.19782831 | K50: -0.29646966 | L50: -0.39511102 | M50: -0.49375237 | N50: -0.59239373 | O50: -0.69103508
C51: -4.9267634 | D51: -4.4244061 | E51: -4.2430893 | F51: -4.7248538 | G51: -6.6156983 | H51: -13.127546 | I51: #NUM! | J51: -13.439467 | K51: -7.4463454 | L51: -6.1649112 | M51: -6.2111882 | N51: -6.7836341 | O51: -7.5835845
C52: 5.9120858 | D52: 5.2124457 | E52: 4.8338462 | F52: 5.118328 | G52: 6.8118899 | H52: 13.126455 | I52: #NUM! | J52: 13.04381 | K52: 6.8534061 | L52: 5.3746892 | M52: 5.2236835 | N52: 5.5988466 | O52: 6.2015144
B54: ##-- From aov(.) example ---- predict(.. terms)
B55: npk.aov <- aov(yield ~ block + N*P*K, npk) | C55: {=TRANSPOSE(_xll.RScript.Evaluate(B55))} -> npk.aov
B56: termL <- attr(terms(npk.aov), "term.labels") | C56: {=TRANSPOSE(_xll.RScript.Evaluate(B56))} -> termL
B57: pt <- predict(npk.aov, type = "terms") | C57: {=TRANSPOSE(_xll.RScript.Evaluate(B57))} -> pt
B58: pt. <- predict(npk.aov, type = "terms", terms = termL[1:4]) | C58: {=TRANSPOSE(_xll.RScript.Evaluate(B58))} -> pt.
B59: stopifnot(all.equal(pt[,1:4], pt., tolerance = 1e-12, check.attributes = FALSE)) | C59: {=TRANSPOSE(_xll.RScript.Evaluate(B59))} -> OK
